2023-09-22 09:34:29,744 - root - ERROR - 'int' object has no attribute 'loc'
Traceback (most recent call last):
  File "e:\zc\GitProjects\algorithm-platform\platform\head_move\server.py", line 408, in sd_cervical
    magnitudes = sd_cervical.get_magnitude()
  File "e:\zc\GitProjects\algorithm-platform\platform\head_move\Cervical.py", line 44, in get_magnitude
    raise e
  File "e:\zc\GitProjects\algorithm-platform\platform\head_move\Cervical.py", line 29, in get_magnitude
    df_action_1 = self.df.loc[(self.df['level'] == 1) | (self.df['level'] == 2)].describe()
AttributeError: 'int' object has no attribute 'loc'
2023-09-22 09:34:29,746 - werkzeug - INFO - 127.0.0.1 - - [22/Sep/2023 09:34:29] "[37mPOST /rehab/sd/cervical HTTP/1.1[0m" 200 -
